Workbook

Sheet Read Me
A1: Medibook — Production Readiness Test Checklist
A2: Patient mobile app (Flutter, Android + iOS) · end-to-end manual test pass before release
A4: Run details
A5: Build / version under test
A6: Environment (API host)
A7: Test cycle
A8: Start date
A9: End date
A10: QA lead
A12: How to use this workbook
A13: 1. Known Blockers — re-verify each item first. Many checklist rows cannot run until these are resolved.
A14: 2. Checklist — start with module 00 (prerequisites) and 01 (end-to-end journeys), then work down. Filter by Module, Priority or Platform.
... A23: Status values
A24: Not Run | B24: Not executed yet (default).
A25: Pass | B25: Behaved exactly as the Expected result says.
A26: Fail | B26: Did not — log a defect.
A27: Blocked | B27: Could not be run (environment, blocker, dependency). Say why in Notes.
A28: N/A | B28: Does not apply to this release. Say why in Notes.
A30: Priority
A31: P0 | B31: Release blocker: money, sign-in, data loss, security, privacy, store rejection, or a core journey.
A32: P1 | B32: Must be fixed before public launch; acceptable only for a limited internal beta.
A33: P2 | B33: Should be fixed; a visible flaw with a workaround.
A34: P3 | B34: Polish.
A36: Check types on the Business Logic sheet
A37: Rule | B37: A decision the app makes (who may do what, and when).
A38: Boundary | B38: A limit: lengths, sizes, ages, time windows, counts. Test just inside and just outside.
A39: State | B39: What changes after an action, and what is kept or cleared.
A40: Calculation | B40: A derived value: amounts, percentages, counts, dates, labels built from data.
A41: Data mapping | B41: A server value shown as the right label or screen.
A42: Error handling | B42: A specific refusal or failure and the message it must produce.
A43: Verify gap | B43: The code appears to behave differently from what a user or the API contract would expect. Found by reading the code, not by running the app — confirm on a device, then log a defect or mark N/A with the owner's decision.
A45: Example of a filled-in checklist row
A46: ID | B46: Test case | C46: Notes / Actual result | D46: Status | E46: Tester | F46: Date tested | G46: Build | H46: Device / OS
A47: AUTH-019 | B47: Wrong password | C47: Shows 'attempts remaining: 4'. Fields stay filled. | D47: Pass | E47: A. Tester | F47: 06-Oct-2026 | G47: 1.0.0+7 | H47: Pixel 8 / Android 15
A49: Where the test cases come from
A50: Screens and routes | B50: lib/app/router/app_routes.dart and the screen files under lib/features/*/presentation/screen
A51: Expected API behaviour | B51: docs-flutter/FLUTTER_API_INTEGRATION.md (error codes, limits, timers, idempotency, token lifecycle)
A52: Business rules | B52: Read from the domain, application and controller code of each feature (lib/features/*/domain, */application, */presentation/controllers) and lib/core; each row cites its file.
A53: Cache scenarios | B53: docs-flutter/HIVE implementation.md (the ten scenarios) and lib/core/storage/hive/boxes.dart (CacheConfig)
A54: Code quality gates | B54: docs-flutter/QA.md (audit prompts 1–5 and the architecture audit)
...

Sheet Summary
A1: Medibook — Production Readiness Test Summary
A2: Every figure on this sheet is a formula over the Checklist sheet. Do not type over them.
A4: Release gate
A5: P0 cases not yet passed | B5: =COUNTIF(Checklist!$G$2:$G$1000,"P0")+COUNTIF('Business Logic'!$G$2:$G$1000,"P0")-(COUNTIFS(Checklist!$G$2:$G$1000,"P0",Checklist!$K$2:$K$1000,"Pass")+COUNTIFS('Business Logic'!$G$2:$G$1000,"P0",'Business Logic'!$K$2:$K$1000,"Pass"))-(COUNTIFS(Checklist!$G$2:$G$1000,"P0",Checklist!$K$2:$K$1000,"N/A")+COUNTIFS('Business Logic'!$G$2:$G$1000,"P0",'Business Logic'!$K$2:$K$1000,"N/A")) | C5: Every P0 must be Pass (or N/A with a written reason).
A6: P0 / P1 cases failing | B6: =COUNTIFS(Checklist!$G$2:$G$1000,"P0",Checklist!$K$2:$K$1000,"Fail")+COUNTIFS('Business Logic'!$G$2:$G$1000,"P0",'Business Logic'!$K$2:$K$1000,"Fail")+COUNTIFS(Checklist!$G$2:$G$1000,"P1",Checklist!$K$2:$K$1000,"Fail")+COUNTIFS('Business Logic'!$G$2:$G$1000,"P1",'Business Logic'!$K$2:$K$1000,"Fail") | C6: No open P0 or P1 failures.
A7: Cases blocked | B7: =COUNTIF(Checklist!$K$2:$K$1000,"Blocked")+COUNTIF('Business Logic'!$K$2:$K$1000,"Blocked") | C7: Blocked cases must be unblocked or accepted on the Sign-off sheet.
A8: Known blockers still open | B8: ='Known Blockers'!$I$1 | C8: From the Known Blockers sheet.
A9: Verdict | B9: =IF(AND(B5=0,B6=0,B7=0,B8=0),"GO","NO-GO") | C9: GO only when the four counts above are all zero. Counts cover the Checklist and Business Logic sheets together.
A11: Progress by priority (both sheets)
A12: Priority | B12: Total | C12: Pass | D12: Fail | E12: Blocked | F12: N/A | G12: Not Run | H12: % executed | I12: Pass rate
A13: P0 — release blocker | B13: =COUNTIF(Checklist!$G$2:$G$1000,"P0")+COUNTIF('Business Logic'!$G$2:$G$1000,"P0") | C13: =COUNTIFS(Checklist!$G$2:$G$1000,"P0",Checklist!$K$2:$K$1000,"Pass")+COUNTIFS('Business Logic'!$G$2:$G$1000,"P0",'Business Logic'!$K$2:$K$1000,"Pass") | D13: =COUNTIFS(Checklist!$G$2:$G$1000,"P0",Checklist!$K$2:$K$1000,"Fail")+COUNTIFS('Business Logic'!$G$2:$G$1000,"P0",'Business Logic'!$K$2:$K$1000,"Fail") | E13: =COUNTIFS(Checklist!$G$2:$G$1000,"P0",Checklist!$K$2:$K$1000,"Blocked")+COUNTIFS('Business Logic'!$G$2:$G$1000,"P0",'Business Logic'!$K$2:$K$1000,"Blocked") | F13: =COUNTIFS(Checklist!$G$2:$G$1000,"P0",Checklist!$K$2:$K$1000,"N/A")+COUNTIFS('Business Logic'!$G$2:$G$1000,"P0",'Business Logic'!$K$2:$K$1000,"N/A") | G13: =COUNTIFS(Checklist!$G$2:$G$1000,"P0",Checklist!$K$2:$K$1000,"Not Run")+COUNTIFS('Business Logic'!$G$2:$G$1000,"P0",'Business Logic'!$K$2:$K$1000,"Not Run") | H13: =IF(B13=0,0,(B13-G13)/B13) | I13: =IF(C13+D13=0,0,C13/(C13+D13))
A14: P1 — must fix before launch | B14: =COUNTIF(Checklist!$G$2:$G$1000,"P1")+COUNTIF('Business Logic'!$G$2:$G$1000,"P1") | C14: =COUNTIFS(Checklist!$G$2:$G$1000,"P1",Checklist!$K$2:$K$1000,"Pass")+COUNTIFS('Business Logic'!$G$2:$G$1000,"P1",'Business Logic'!$K$2:$K$1000,"Pass") | D14: =COUNTIFS(Checklist!$G$2:$G$1000,"P1",Checklist!$K$2:$K$1000,"Fail")+COUNTIFS('Business Logic'!$G$2:$G$1000,"P1",'Business Logic'!$K$2:$K$1000,"Fail") | E14: =COUNTIFS(Checklist!$G$2:$G$1000,"P1",Checklist!$K$2:$K$1000,"Blocked")+COUNTIFS('Business Logic'!$G$2:$G$1000,"P1",'Business Logic'!$K$2:$K$1000,"Blocked") | F14: =COUNTIFS(Checklist!$G$2:$G$1000,"P1",Checklist!$K$2:$K$1000,"N/A")+COUNTIFS('Business Logic'!$G$2:$G$1000,"P1",'Business Logic'!$K$2:$K$1000,"N/A") | G14: =COUNTIFS(Checklist!$G$2:$G$1000,"P1",Checklist!$K$2:$K$1000,"Not Run")+COUNTIFS('Business Logic'!$G$2:$G$1000,"P1",'Business Logic'!$K$2:$K$1000,"Not Run") | H14: =IF(B14=0,0,(B14-G14)/B14) | I14: =IF(C14+D14=0,0,C14/(C14+D14))
A15: P2 — should fix | B15: =COUNTIF(Checklist!$G$2:$G$1000,"P2")+COUNTIF('Business Logic'!$G$2:$G$1000,"P2") | C15: =COUNTIFS(Checklist!$G$2:$G$1000,"P2",Checklist!$K$2:$K$1000,"Pass")+COUNTIFS('Business Logic'!$G$2:$G$1000,"P2",'Business Logic'!$K$2:$K$1000,"Pass") | D15: =COUNTIFS(Checklist!$G$2:$G$1000,"P2",Checklist!$K$2:$K$1000,"Fail")+COUNTIFS('Business Logic'!$G$2:$G$1000,"P2",'Business Logic'!$K$2:$K$1000,"Fail") | E15: =COUNTIFS(Checklist!$G$2:$G$1000,"P2",Checklist!$K$2:$K$1000,"Blocked")+COUNTIFS('Business Logic'!$G$2:$G$1000,"P2",'Business Logic'!$K$2:$K$1000,"Blocked") | F15: =COUNTIFS(Checklist!$G$2:$G$1000,"P2",Checklist!$K$2:$K$1000,"N/A")+COUNTIFS('Business Logic'!$G$2:$G$1000,"P2",'Business Logic'!$K$2:$K$1000,"N/A") | G15: =COUNTIFS(Checklist!$G$2:$G$1000,"P2",Checklist!$K$2:$K$1000,"Not Run")+COUNTIFS('Business Logic'!$G$2:$G$1000,"P2",'Business Logic'!$K$2:$K$1000,"Not Run") | H15: =IF(B15=0,0,(B15-G15)/B15) | I15: =IF(C15+D15=0,0,C15/(C15+D15))
A16: P3 — nice to have | B16: =COUNTIF(Checklist!$G$2:$G$1000,"P3")+COUNTIF('Business Logic'!$G$2:$G$1000,"P3") | C16: =COUNTIFS(Checklist!$G$2:$G$1000,"P3",Checklist!$K$2:$K$1000,"Pass")+COUNTIFS('Business Logic'!$G$2:$G$1000,"P3",'Business Logic'!$K$2:$K$1000,"Pass") | D16: =COUNTIFS(Checklist!$G$2:$G$1000,"P3",Checklist!$K$2:$K$1000,"Fail")+COUNTIFS('Business Logic'!$G$2:$G$1000,"P3",'Business Logic'!$K$2:$K$1000,"Fail") | E16: =COUNTIFS(Checklist!$G$2:$G$1000,"P3",Checklist!$K$2:$K$1000,"Blocked")+COUNTIFS('Business Logic'!$G$2:$G$1000,"P3",'Business Logic'!$K$2:$K$1000,"Blocked") | F16: =COUNTIFS(Checklist!$G$2:$G$1000,"P3",Checklist!$K$2:$K$1000,"N/A")+COUNTIFS('Business Logic'!$G$2:$G$1000,"P3",'Business Logic'!$K$2:$K$1000,"N/A") | G16: =COUNTIFS(Checklist!$G$2:$G$1000,"P3",Checklist!$K$2:$K$1000,"Not Run")+COUNTIFS('Business Logic'!$G$2:$G$1000,"P3",'Business Logic'!$K$2:$K$1000,"Not Run") | H16: =IF(B16=0,0,(B16-G16)/B16) | I16: =IF(C16+D16=0,0,C16/(C16+D16))
A17: All cases | B17: =COUNTA(Checklist!$A$2:$A$1000)+COUNTA('Business Logic'!$A$2:$A$1000) | C17: =COUNTIF(Checklist!$K$2:$K$1000,"Pass")+COUNTIF('Business Logic'!$K$2:$K$1000,"Pass") | D17: =COUNTIF(Checklist!$K$2:$K$1000,"Fail")+COUNTIF('Business Logic'!$K$2:$K$1000,"Fail") | E17: =COUNTIF(Checklist!$K$2:$K$1000,"Blocked")+COUNTIF('Business Logic'!$K$2:$K$1000,"Blocked") | F17: =COUNTIF(Checklist!$K$2:$K$1000,"N/A")+COUNTIF('Business Logic'!$K$2:$K$1000,"N/A") | G17: =COUNTIF(Checklist!$K$2:$K$1000,"Not Run")+COUNTIF('Business Logic'!$K$2:$K$1000,"Not Run") | H17: =IF(B17=0,0,(B17-G17)/B17) | I17: =IF(C17+D17=0,0,C17/(C17+D17))
A18: of which: Checklist sheet | B18: =COUNTA(Checklist!$A$2:$A$1000) | C18: =COUNTIF(Checklist!$K$2:$K$1000,"Pass") | D18: =COUNTIF(Checklist!$K$2:$K$1000,"Fail") | E18: =COUNTIF(Checklist!$K$2:$K$1000,"Blocked") | F18: =COUNTIF(Checklist!$K$2:$K$1000,"N/A") | G18: =COUNTIF(Checklist!$K$2:$K$1000,"Not Run") | H18: =IF(B18=0,0,(B18-G18)/B18) | I18: =IF(C18+D18=0,0,C18/(C18+D18))
A19: of which: Business Logic sheet | B19: =COUNTA('Business Logic'!$A$2:$A$1000) | C19: =COUNTIF('Business Logic'!$K$2:$K$1000,"Pass") | D19: =COUNTIF('Business Logic'!$K$2:$K$1000,"Fail") | E19: =COUNTIF('Business Logic'!$K$2:$K$1000,"Blocked") | F19: =COUNTIF('Business Logic'!$K$2:$K$1000,"N/A") | G19: =COUNTIF('Business Logic'!$K$2:$K$1000,"Not Run") | H19: =IF(B19=0,0,(B19-G19)/B19) | I19: =IF(C19+D19=0,0,C19/(C19+D19))
A21: Business logic — progress by module
A22: Module | B22: Total | C22: Pass | D22: Fail | E22: Blocked | F22: N/A | G22: Not Run | H22: % executed | I22: Pass rate
A23: Authentication & session | B23: =COUNTIF('Business Logic'!$B$2:$B$1000,$A23) | C23: =COUNTIFS('Business Logic'!$B$2:$B$1000,$A23,'Business Logic'!$K$2:$K$1000,"Pass") | D23: =COUNTIFS('Business Logic'!$B$2:$B$1000,$A23,'Business Logic'!$K$2:$K$1000,"Fail") | E23: =COUNTIFS('Business Logic'!$B$2:$B$1000,$A23,'Business Logic'!$K$2:$K$1000,"Blocked") | F23: =COUNTIFS('Business Logic'!$B$2:$B$1000,$A23,'Business Logic'!$K$2:$K$1000,"N/A") | G23: =COUNTIFS('Business Logic'!$B$2:$B$1000,$A23,'Business Logic'!$K$2:$K$1000,"Not Run") | H23: =IF(B23=0,0,(B23-G23)/B23) | I23: =IF(C23+D23=0,0,C23/(C23+D23))
A24: Booking | B24: =COUNTIF('Business Logic'!$B$2:$B$1000,$A24) | C24: =COUNTIFS('Business Logic'!$B$2:$B$1000,$A24,'Business Logic'!$K$2:$K$1000,"Pass") | D24: =COUNTIFS('Business Logic'!$B$2:$B$1000,$A24,'Business Logic'!$K$2:$K$1000,"Fail") | E24: =COUNTIFS('Business Logic'!$B$2:$B$1000,$A24,'Business Logic'!$K$2:$K$1000,"Blocked") | F24: =COUNTIFS('Business Logic'!$B$2:$B$1000,$A24,'Business Logic'!$K$2:$K$1000,"N/A") | G24: =COUNTIFS('Business Logic'!$B$2:$B$1000,$A24,'Business Logic'!$K$2:$K$1000,"Not Run") | H24: =IF(B24=0,0,(B24-G24)/B24) | I24: =IF(C24+D24=0,0,C24/(C24+D24))
A25: Payment | B25: =COUNTIF('Business Logic'!$B$2:$B$1000,$A25) | C25: =COUNTIFS('Business Logic'!$B$2:$B$1000,$A25,'Business Logic'!$K$2:$K$1000,"Pass") | D25: =COUNTIFS('Business Logic'!$B$2:$B$1000,$A25,'Business Logic'!$K$2:$K$1000,"Fail") | E25: =COUNTIFS('Business Logic'!$B$2:$B$1000,$A25,'Business Logic'!$K$2:$K$1000,"Blocked") | F25: =COUNTIFS('Business Logic'!$B$2:$B$1000,$A25,'Business Logic'!$K$2:$K$1000,"N/A") | G25: =COUNTIFS('Business Logic'!$B$2:$B$1000,$A25,'Business Logic'!$K$2:$K$1000,"Not Run") | H25: =IF(B25=0,0,(B25-G25)/B25) | I25: =IF(C25+D25=0,0,C25/(C25+D25))
A26: Appointments | B26: =COUNTIF('Business Logic'!$B$2:$B$1000,$A26) | C26: =COUNTIFS('Business Logic'!$B$2:$B$1000,$A26,'Business Logic'!$K$2:$K$1000,"Pass") | D26: =COUNTIFS('Business Logic'!$B$2:$B$1000,$A26,'Business Logic'!$K$2:$K$1000,"Fail") | E26: =COUNTIFS('Business Logic'!$B$2:$B$1000,$A26,'Business Logic'!$K$2:$K$1000,"Blocked") | F26: =COUNTIFS('Business Logic'!$B$2:$B$1000,$A26,'Business Logic'!$K$2:$K$1000,"N/A") | G26: =COUNTIFS('Business Logic'!$B$2:$B$1000,$A26,'Business Logic'!$K$2:$K$1000,"Not Run") | H26: =IF(B26=0,0,(B26-G26)/B26) | I26: =IF(C26+D26=0,0,C26/(C26+D26))
A27: Live queue | B27: =COUNTIF('Business Logic'!$B$2:$B$1000,$A27) | C27: =COUNTIFS('Business Logic'!$B$2:$B$1000,$A27,'Business Logic'!$K$2:$K$1000,"Pass") | D27: =COUNTIFS('Business Logic'!$B$2:$B$1000,$A27,'Business Logic'!$K$2:$K$1000,"Fail") | E27: =COUNTIFS('Business Logic'!$B$2:$B$1000,$A27,'Business Logic'!$K$2:$K$1000,"Blocked") | F27: =COUNTIFS('Business Logic'!$B$2:$B$1000,$A27,'Business Logic'!$K$2:$K$1000,"N/A") | G27: =COUNTIFS('Business Logic'!$B$2:$B$1000,$A27,'Business Logic'!$K$2:$K$1000,"Not Run") | H27: =IF(B27=0,0,(B27-G27)/B27) | I27: =IF(C27+D27=0,0,C27/(C27+D27))
A28: Home & search | B28: =COUNTIF('Business Logic'!$B$2:$B$1000,$A28) | C28: =COUNTIFS('Business Logic'!$B$2:$B$1000,$A28,'Business Logic'!$K$2:$K$1000,"Pass") | D28: =COUNTIFS('Business Logic'!$B$2:$B$1000,$A28,'Business Logic'!$K$2:$K$1000,"Fail") | E28: =COUNTIFS('Business Logic'!$B$2:$B$1000,$A28,'Business Logic'!$K$2:$K$1000,"Blocked") | F28: =COUNTIFS('Business Logic'!$B$2:$B$1000,$A28,'Business Logic'!$K$2:$K$1000,"N/A") | G28: =COUNTIFS('Business Logic'!$B$2:$B$1000,$A28,'Business Logic'!$K$2:$K$1000,"Not Run") | H28: =IF(B28=0,0,(B28-G28)/B28) | I28: =IF(C28+D28=0,0,C28/(C28+D28))
A29: Records & uploads | B29: =COUNTIF('Business Logic'!$B$2:$B$1000,$A29) | C29: =COUNTIFS('Business Logic'!$B$2:$B$1000,$A29,'Business Logic'!$K$2:$K$1000,"Pass") | D29: =COUNTIFS('Business Logic'!$B$2:$B$1000,$A29,'Business Logic'!$K$2:$K$1000,"Fail") | E29: =COUNTIFS('Business Logic'!$B$2:$B$1000,$A29,'Business Logic'!$K$2:$K$1000,"Blocked") | F29: =COUNTIFS('Business Logic'!$B$2:$B$1000,$A29,'Business Logic'!$K$2:$K$1000,"N/A") | G29: =COUNTIFS('Business Logic'!$B$2:$B$1000,$A29,'Business Logic'!$K$2:$K$1000,"Not Run") | H29: =IF(B29=0,0,(B29-G29)/B29) | I29: =IF(C29+D29=0,0,C29/(C29+D29))
A30: Cache, offline & pagination | B30: =COUNTIF('Business Logic'!$B$2:$B$1000,$A30) | C30: =COUNTIFS('Business Logic'!$B$2:$B$1000,$A30,'Business Logic'!$K$2:$K$1000,"Pass") | D30: =COUNTIFS('Business Logic'!$B$2:$B$1000,$A30,'Business Logic'!$K$2:$K$1000,"Fail") | E30: =COUNTIFS('Business Logic'!$B$2:$B$1000,$A30,'Business Logic'!$K$2:$K$1000,"Blocked") | F30: =COUNTIFS('Business Logic'!$B$2:$B$1000,$A30,'Business Logic'!$K$2:$K$1000,"N/A") | G30: =COUNTIFS('Business Logic'!$B$2:$B$1000,$A30,'Business Logic'!$K$2:$K$1000,"Not Run") | H30: =IF(B30=0,0,(B30-G30)/B30) | I30: =IF(C30+D30=0,0,C30/(C30+D30))
A31: Notifications | B31: =COUNTIF('Business Logic'!$B$2:$B$1000,$A31) | C31: =COUNTIFS('Business Logic'!$B$2:$B$1000,$A31,'Business Logic'!$K$2:$K$1000,"Pass") | D31: =COUNTIFS('Business Logic'!$B$2:$B$1000,$A31,'Business Logic'!$K$2:$K$1000,"Fail") | E31: =COUNTIFS('Business Logic'!$B$2:$B$1000,$A31,'Business Logic'!$K$2:$K$1000,"Blocked") | F31: =COUNTIFS('Business Logic'!$B$2:$B$1000,$A31,'Business Logic'!$K$2:$K$1000,"N/A") | G31: =COUNTIFS('Business Logic'!$B$2:$B$1000,$A31,'Business Logic'!$K$2:$K$1000,"Not Run") | H31: =IF(B31=0,0,(B31-G31)/B31) | I31: =IF(C31+D31=0,0,C31/(C31+D31))
A32: Profile & account | B32: =COUNTIF('Business Logic'!$B$2:$B$1000,$A32) | C32: =COUNTIFS('Business Logic'!$B$2:$B$1000,$A32,'Business Logic'!$K$2:$K$1000,"Pass") | D32: =COUNTIFS('Business Logic'!$B$2:$B$1000,$A32,'Business Logic'!$K$2:$K$1000,"Fail") | E32: =COUNTIFS('Business Logic'!$B$2:$B$1000,$A32,'Business Logic'!$K$2:$K$1000,"Blocked") | F32: =COUNTIFS('Business Logic'!$B$2:$B$1000,$A32,'Business Logic'!$K$2:$K$1000,"N/A") | G32: =COUNTIFS('Business Logic'!$B$2:$B$1000,$A32,'Business Logic'!$K$2:$K$1000,"Not Run") | H32: =IF(B32=0,0,(B32-G32)/B32) | I32: =IF(C32+D32=0,0,C32/(C32+D32))
A33: Family members | B33: =COUNTIF('Business Logic'!$B$2:$B$1000,$A33) | C33: =COUNTIFS('Business Logic'!$B$2:$B$1000,$A33,'Business Logic'!$K$2:$K$1000,"Pass") | D33: =COUNTIFS('Business Logic'!$B$2:$B$1000,$A33,'Business Logic'!$K$2:$K$1000,"Fail") | E33: =COUNTIFS('Business Logic'!$B$2:$B$1000,$A33,'Business Logic'!$K$2:$K$1000,"Blocked") | F33: =COUNTIFS('Business Logic'!$B$2:$B$1000,$A33,'Business Logic'!$K$2:$K$1000,"N/A") | G33: =COUNTIFS('Business Logic'!$B$2:$B$1000,$A33,'Business Logic'!$K$2:$K$1000,"Not Run") | H33: =IF(B33=0,0,(B33-G33)/B33) | I33: =IF(C33+D33=0,0,C33/(C33+D33))
A34: Insurance | B34: =COUNTIF('Business Logic'!$B$2:$B$1000,$A34) | C34: =COUNTIFS('Business Logic'!$B$2:$B$1000,$A34,'Business Logic'!$K$2:$K$1000,"Pass") | D34: =COUNTIFS('Business Logic'!$B$2:$B$1000,$A34,'Business Logic'!$K$2:$K$1000,"Fail") | E34: =COUNTIFS('Business Logic'!$B$2:$B$1000,$A34,'Business Logic'!$K$2:$K$1000,"Blocked") | F34: =COUNTIFS('Business Logic'!$B$2:$B$1000,$A34,'Business Logic'!$K$2:$K$1000,"N/A") | G34: =COUNTIFS('Business Logic'!$B$2:$B$1000,$A34,'Business Logic'!$K$2:$K$1000,"Not Run") | H34: =IF(B34=0,0,(B34-G34)/B34) | I34: =IF(C34+D34=0,0,C34/(C34+D34))
... A36: Shared rules: money & time | B36: =COUNTIF('Business Logic'!$B$2:$B$1000,$A36) | C36: =COUNTIFS('Business Logic'!$B$2:$B$1000,$A36,'Business Logic'!$K$2:$K$1000,"Pass") | D36: =COUNTIFS('Business Logic'!$B$2:$B$1000,$A36,'Business Logic'!$K$2:$K$1000,"Fail") | E36: =COUNTIFS('Business Logic'!$B$2:$B$1000,$A36,'Business Logic'!$K$2:$K$1000,"Blocked") | F36: =COUNTIFS('Business Logic'!$B$2:$B$1000,$A36,'Business Logic'!$K$2:$K$1000,"N/A") | G36: =COUNTIFS('Business Logic'!$B$2:$B$1000,$A36,'Business Logic'!$K$2:$K$1000,"Not Run") | H36: =IF(B36=0,0,(B36-G36)/B36) | I36: =IF(C36+D36=0,0,C36/(C36+D36))
A37: Total | B37: =SUM(B23:B36) | C37: =SUM(C23:C36) | D37: =SUM(D23:D36) | E37: =SUM(E23:E36) | F37: =SUM(F23:F36) | G37: =SUM(G23:G36) | H37: =IF(B37=0,0,(B37-G37)/B37) | I37: =IF(C37+D37=0,0,C37/(C37+D37)) | J37: =IF(B37=B19,"","Totals differ: a row on that sheet has a module name not listed here.")
A39: Functional, non-functional & release checklist — progress by module
A40: Module | B40: Total | C40: Pass | D40: Fail | E40: Blocked | F40: N/A | G40: Not Run | H40: % executed | I40: Pass rate
A41: 00 Test environment & prerequisites | B41: =COUNTIF(Checklist!$B$2:$B$1000,$A41) | C41: =COUNTIFS(Checklist!$B$2:$B$1000,$A41,Checklist!$K$2:$K$1000,"Pass") | D41: =COUNTIFS(Checklist!$B$2:$B$1000,$A41,Checklist!$K$2:$K$1000,"Fail") | E41: =COUNTIFS(Checklist!$B$2:$B$1000,$A41,Checklist!$K$2:$K$1000,"Blocked") | F41: =COUNTIFS(Checklist!$B$2:$B$1000,$A41,Checklist!$K$2:$K$1000,"N/A") | G41: =COUNTIFS(Checklist!$B$2:$B$1000,$A41,Checklist!$K$2:$K$1000,"Not Run") | H41: =IF(B41=0,0,(B41-G41)/B41) | I41: =IF(C41+D41=0,0,C41/(C41+D41))
A42: 01 End-to-end journeys (run first) | B42: =COUNTIF(Checklist!$B$2:$B$1000,$A42) | C42: =COUNTIFS(Checklist!$B$2:$B$1000,$A42,Checklist!$K$2:$K$1000,"Pass") | D42: =COUNTIFS(Checklist!$B$2:$B$1000,$A42,Checklist!$K$2:$K$1000,"Fail") | E42: =COUNTIFS(Checklist!$B$2:$B$1000,$A42,Checklist!$K$2:$K$1000,"Blocked") | F42: =COUNTIFS(Checklist!$B$2:$B$1000,$A42,Checklist!$K$2:$K$1000,"N/A") | G42: =COUNTIFS(Checklist!$B$2:$B$1000,$A42,Checklist!$K$2:$K$1000,"Not Run") | H42: =IF(B42=0,0,(B42-G42)/B42) | I42: =IF(C42+D42=0,0,C42/(C42+D42))
A43: 02 Install, launch & bootstrap | B43: =COUNTIF(Checklist!$B$2:$B$1000,$A43) | C43: =COUNTIFS(Checklist!$B$2:$B$1000,$A43,Checklist!$K$2:$K$1000,"Pass") | D43: =COUNTIFS(Checklist!$B$2:$B$1000,$A43,Checklist!$K$2:$K$1000,"Fail") | E43: =COUNTIFS(Checklist!$B$2:$B$1000,$A43,Checklist!$K$2:$K$1000,"Blocked") | F43: =COUNTIFS(Checklist!$B$2:$B$1000,$A43,Checklist!$K$2:$K$1000,"N/A") | G43: =COUNTIFS(Checklist!$B$2:$B$1000,$A43,Checklist!$K$2:$K$1000,"Not Run") | H43: =IF(B43=0,0,(B43-G43)/B43) | I43: =IF(C43+D43=0,0,C43/(C43+D43))
A44: 03 Onboarding & consent | B44: =COUNTIF(Checklist!$B$2:$B$1000,$A44) | C44: =COUNTIFS(Checklist!$B$2:$B$1000,$A44,Checklist!$K$2:$K$1000,"Pass") | D44: =COUNTIFS(Checklist!$B$2:$B$1000,$A44,Checklist!$K$2:$K$1000,"Fail") | E44: =COUNTIFS(Checklist!$B$2:$B$1000,$A44,Checklist!$K$2:$K$1000,"Blocked") | F44: =COUNTIFS(Checklist!$B$2:$B$1000,$A44,Checklist!$K$2:$K$1000,"N/A") | G44: =COUNTIFS(Checklist!$B$2:$B$1000,$A44,Checklist!$K$2:$K$1000,"Not Run") | H44: =IF(B44=0,0,(B44-G44)/B44) | I44: =IF(C44+D44=0,0,C44/(C44+D44))
A45: 04 Authentication & session | B45: =COUNTIF(Checklist!$B$2:$B$1000,$A45) | C45: =COUNTIFS(Checklist!$B$2:$B$1000,$A45,Checklist!$K$2:$K$1000,"Pass") | D45: =COUNTIFS(Checklist!$B$2:$B$1000,$A45,Checklist!$K$2:$K$1000,"Fail") | E45: =COUNTIFS(Checklist!$B$2:$B$1000,$A45,Checklist!$K$2:$K$1000,"Blocked") | F45: =COUNTIFS(Checklist!$B$2:$B$1000,$A45,Checklist!$K$2:$K$1000,"N/A") | G45: =COUNTIFS(Checklist!$B$2:$B$1000,$A45,Checklist!$K$2:$K$1000,"Not Run") | H45: =IF(B45=0,0,(B45-G45)/B45) | I45: =IF(C45+D45=0,0,C45/(C45+D45))
...

Sheet Business Logic
A1: ID | B1: Module | C1: Sub-module | D1: Business rule under test | E1: Steps | F1: Expected result | G1: Priority | H1: Check type | I1: Source in code | J1: Needs / Blocker | K1: Status | L1: Tester | M1: Date tested | N1: Build | O1: Device / OS | P1: Defect ID | Q1: Notes / Actual result
A2: BL-AUTH-001 | B2: Authentication & session | C2: Onboarding & consent | D2: Terms box is required; offers box is optional | E2: 1. On the consent screen tap 'Agree and Continue' with the terms box unticked 2. Tick it | F2: 'Please accept the terms to continue.' and no navigation; the note clears on tick and the user can proceed. | G2: P0 | H2: Rule | I2: lib/features/auth/presentation/controllers/consent_form_controller.dart:68 | K2: Pass | L2: Claude (adb) | M2: 46299 | N2: 1.0.0+1 debug | O2: emulator-5554 / Android 14 | Q2: Agree and Continue with the terms box unticked shows 'Please accept the terms to continue.' and stays; ticking clears the note; offers box is optional; proceeds to sign-in.
A3: BL-AUTH-002 | B3: Authentication & session | C3: Onboarding & consent | D3: Onboarding is recorded once and survives sign-out | E3: 1. Complete onboarding 2. Kill and relaunch 3. Sign in, then log out | F3: Relaunch goes to sign-in; after logout the intro is not shown again. | G3: P1 | H3: State | I3: lib/core/storage/hive/boxes.dart:83 | K3: Pass | L3: Claude (adb) | M3: 46299 | N3: 1.0.0+1 debug | O3: emulator-5554 / Android 14 | Q3: Relaunch after onboarding goes to sign-in; after signing in and logging out (several times, incl. forced sign-out) the app returns to sign-in and never shows the intro again.
A4: BL-AUTH-003 | B4: Authentication & session | C4: Onboarding & consent | D4: Consent can be accepted without the Terms having loaded | E4: 1. Go offline 2. Tick the terms box and accept | F4: Confirm intended: the code lets the user continue and records an empty accepted version. | G4: P2 | H4: Verify gap | I4: lib/features/auth/infrastructure/data_sources/local/onboarding_local_ds.dart:54 | K4: Pass | L4: Claude (adb) | M4: 46299 | N4: 1.0.0+1 debug (rebuilt with fix) | O4: emulator-5554 / Android 14 | P4: DEF-042 | Q4: FIXED AND RETESTED (4 Oct 2026, rebuilt debug build). Before: in airplane mode the terms box could be ticked and accepted although the Terms could not be loaded, and an empty Terms version was stored (owner decision: not acceptable, DEF-042). After the fix: fresh install in airplane mode -> tick the box -> 'Agree and Continue' stays on the consent screen with 'We could not load the Terms & Conditions and Privacy Policy. Check your connection, then tap Agree and Continue again.'; relaunch still shows the intro (nothing recorded). After reconnecting, the same button loads the documents and moves on to sign-in, and the stored accepted Terms version is '1'. The unticked-box note ('Please accept the terms to continue.') still works.
A5: BL-AUTH-004 | B5: Authentication & session | C5: Onboarding & consent | D5: Offers opt-in reaches the account | E5: 1. Tick the offers box in onboarding 2. Sign up 3. Inspect the sign-up request and the profile's marketing preference | F5: Marketing consent should reflect the choice. The code always sends marketing = false at sign-up. | G5: P1 | H5: Verify gap | I5: lib/features/auth/presentation/controllers/auth_flow_draft.dart:91 | J5: KB-05 | K5: Blocked | L5: Claude (adb) | M5: 46299 | N5: 1.0.0+1 debug | O5: emulator-5554 / Android 14 | Q5: Fixed 04-Oct-2026: sign-up now sends the onboarding offers choice (lib/features/auth/presentation/controllers/signup_form_controller.dart, startMobileVerification). Retest on the fixed build, offers box ticked in onboarding: the signup/start body captured on a local recording server (app pointed at http://10.0.2.2:8000) carries consents.marketing = true; unit tests cover ticked and unticked (test/features/auth/signup_server_errors_test.dart). Still blocked for the account half by KB-05: sign-up with +91 9746863592 on the integration server reached 'Verify Mobile' but no SMS arrived (resend tried once), so the account was not created and the profile's marketing preference could not be checked.
A6: BL-AUTH-005 | B6: Authentication & session | C6: Onboarding & consent | D6: Intro can be skipped by a deep link | E6: 1. Fresh install 2. Open medibook://login or medibook://signup | F6: Decide what is correct: the code opens sign-in / sign-up directly, skipping the intro and consent screen (sign-up has its own legal checkbox). | G6: P2 | H6: Verify gap | I6: lib/app/router/app_router.dart:466 | K6: Pass | L6: Claude (adb) | M6: 46299 | N6: 1.0.0+1 debug | O6: emulator-5554 / Android 14 | P6: DEF-043 | Q6: FIXED AND RETESTED (4 Oct 2026, rebuilt debug build). Owner decision (4 Oct 2026): links must never skip the intro (DEF-043). Before: with the app already open on the intro (not completed), medibook://signup and medibook://login opened Create Account / sign-in directly, skipping the intro and consent screen. After the fix, on a fresh install: with the app open on the intro, medibook://signup, medibook://login and https://medibook.app/login (sent straight to the app) all stay on the intro; opened from the consent screen they go back to the intro; a cold start with either medibook:// link shows the intro. After completing the intro, medibook://signup opens Create Account and medibook://login opens sign-in. The Terms link on the consent screen still opens the document. Routing tests added in test/app/sign_in_routing_test.dart.
A7: BL-AUTH-006 | B7: Authentication & session | C7: Sign-up | D7: First name rules | E7: Submit with first name empty, 'A', and 'An1ta' | F7: 'Enter your first name' / 'Name is too short' / 'Use letters only'. Names like D'Souza and Anne-Marie pass. | G7: P1 | H7: Boundary | I7: lib/features/auth/presentation/controllers/signup_form_controller.dart:58 | K7: Pass | L7: Claude (adb) | M7: 46299 | N7: 1.0.0+1 debug | O7: emulator-5554 / Android 14 | Q7: Empty: 'Enter your first name'; 'A': 'Name is too short'; 'An1ta': 'Use letters only'; D'Souza accepted.
A8: BL-AUTH-007 | B8: Authentication & session | C8: Sign-up | D8: Mobile number is an Indian mobile: 10 digits starting 6–9 | E8: Submit empty, 9 digits, and a number starting with 5 | F8: 'Enter your mobile number' / 'Mobile number must be 10 digits' / 'Mobile number must start with 6-9'. | G8: P0 | H8: Boundary | I8: lib/core/utils/validators.dart:54 | K8: Pass | L8: Claude (adb) | M8: 46299 | N8: 1.0.0+1 debug | O8: emulator-5554 / Android 14 | Q8: Empty: 'Enter your mobile number'; 9 digits: 'Mobile number must be 10 digits'; starting 5: 'Mobile number must start with 6-9' (same on sign-in Mobile tab).
A9: BL-AUTH-008 | B9: Authentication & session | C9: Sign-up | D9: Non-Indian country codes | E9: 1. Pick +971 in the country picker 2. Enter a valid 9-digit UAE number | F9: Decide what is correct: the picker offers other countries, but validation is always the Indian rule, so the number is rejected. | G9: P2 | H9: Verify gap | I9: lib/core/widgets/app_phone_field.dart:68 | K9: Pass | L9: Claude (adb) | M9: 46300 | N9: 1.0.0+1 debug | O9: emulator-5554 / Android 14 | P9: DEF-001 | Q9: FIXED AND RETESTED (5 Oct 2026, rebuilt debug build; DEF-001). The API takes only Indian mobiles for sign-in, sign-up, password reset, number change and family hand-over (§2: ^\+91[6-9]\d{9}$), so those screens are now fixed to +91: the country chip is not tappable and no picker opens (login_screen, signup_screen, forgot_password_screen, phone_change_screen, dependant_edit_screen release sheet). Emergency contacts, the alternate number and a family member's own phone keep the picker - the API accepts any E.164 there and those fields already validate foreign numbers. Emulator: signed out, Mobile tab shows 'Country code +91 India' (not clickable); tapping it opens nothing (+971 not shown). Test added (sign_in_routing_test.dart). First observed: Country picker offers +971 (and 8 other non-Indian codes); with +971 selected a valid 9-digit UAE mobile (501234567) is rejected with 'Mobile number must be 10 digits'. The non-Indian options can never be used.
A10: BL-AUTH-009 | B10: Authentication & session | C10: Sign-up | D10: Account holder must be 18 or older | E10: 1. Open the date picker and look for dates under 18 years ago 2. Force an under-age date via the server | F10: Picker stops at today minus 18 years; a server refusal shows the 18+ message under Date of birth. | G10: P0 | H10: Boundary | I10: lib/features/auth/presentation/controllers/signup_form_controller.dart:97 | K10: Pass | L10: Claude (adb) | M10: 46299 | N10: 1.0.0+1 debug | O10: emulator-5554 / Android 14 | Q10: Date picker opens on 4 Oct 2008 (today minus 18 years); 5 Oct 2008 onward is 'Out of range' and Next month/year are disabled. Server-side under-age refusal not exercised (cannot bypass the picker). Note: the Date of Birth label, placeholder and its error 'Select a date of birth' are drawn on screen but missing from the accessibility tree.
A11: BL-AUTH-010 | B11: Authentication & session | C11: Sign-up | D11: Password is optional; if given, at least 10 characters and confirmed | E11: 1. Leave both password fields empty 2. Enter 9 characters 3. Enter 10 with a different confirmation | F11: Empty is accepted (code-only account); 'At least 10 characters'; 'Passwords do not match'. | G11: P0 | H11: Boundary | I11: lib/features/auth/presentation/controllers/signup_form_controller.dart:71 | K11: Pass | L11: Claude (adb) | M11: 46299 | N11: 1.0.0+1 debug | O11: emulator-5554 / Android 14 | Q11: Both empty: no password error on submit. 9 chars: 'At least 10 characters'. 10 chars with different confirmation: 'Passwords do not match'.
A12: BL-AUTH-011 | B12: Authentication & session | C12: Sign-up | D12: Password containing personal details | E12: Use a 10+ character password containing your first name or phone number | F12: Server refuses it and the message appears under the password field (the app does not pre-check this). | G12: P2 | H12: Error handling | I12: lib/core/utils/validators.dart:30 | K12: Pass | L12: Claude (adb) | M12: 46299 | N12: 1.0.0+1 debug | O12: emulator-5554 / Android 14 | Q12: Password containing the phone number (9123456791ab) passes the app's checks; the server refuses and 'The password must not contain your name, email or phone number.' is shown under the password field.
A13: BL-AUTH-012 | B13: Authentication & session | C13: Sign-up | D13: Address is all-or-nothing | E13: 1. Fill only City and submit 2. Enter PIN 012345 3. Enter line 1 'abc' | F13: Once any of line 1 / city / state / PIN is filled all four are required; 'Enter a valid PIN code'; 'Address looks too short'. Label alone does not trigger it. | G13: P2 | H13: Rule | I13: lib/features/auth/presentation/controllers/signup_form_controller.dart:166 | K13: Pass | L13: Claude (adb) | M13: 46299 | N13: 1.0.0+1 debug | O13: emulator-5554 / Android 14 | Q13: With only City filled: 'Enter a street address', 'Enter a state', 'Enter a PIN code'. PIN 012345: 'Enter a valid PIN code'; 5 digits: 'PIN code must be 6 digits'; line 1 'abc': 'Address looks too short'. Label alone ('Home' prefilled) does not trigger it.
A14: BL-AUTH-013 | B14: Authentication & session | C14: Sign-up | D14: Legal checkbox is required | E14: Submit with the box unticked | F14: 'Accept the Terms, Privacy Policy and User Guidelines to continue'. | G14: P0 | H14: Rule | I14: lib/features/auth/presentation/controllers/signup_form_controller.dart:89 | K14: Pass | L14: Claude (adb) | M14: 46299 | N14: 1.0.0+1 debug | O14: emulator-5554 / Android 14 | Q14: Submitting with the legal box unticked shows 'Accept the Terms, Privacy Policy and User Guidelines to continue'.
A15: BL-AUTH-014 | B15: Authentication & session | C15: Sign-up | D15: No account exists until the code is verified | E15: 1. Submit a valid form 2. On the verify screen press Back 3. Try to sign in with those details | F15: Form is refilled except the password fields; sign-in fails because no account was created yet. | G15: P1 | H15: State | I15: lib/features/auth/presentation/controllers/signup_form_controller.dart:200 | J15: KB-05 | K15: Pass | L15: Claude (adb) | M15: 46299 | N15: 1.0.0+1 debug | O15: emulator-5554 / Android 14 | Q15: Valid form -> 'Verify Mobile … Verify & Create Account'. Back returns to the form with name, mobile, date of birth and address refilled and both password fields empty. API sign-in with those details: AUTH_INVALID_CREDENTIALS (no account created).
A16: BL-AUTH-015 | B16: Authentication & session | C16: Sign-up | D16: Server errors land on their fields | E16: 1. Use an already-registered number 2. Trigger server errors on email and address fields | F16: Each message under its own field (phone, email, date of birth, password, address lines, consents); anything else in the form banner. | G16: P1 | H16: Error handling | I16: lib/features/auth/presentation/controllers/signup_form_controller.dart:225 | K16: Pass | L16: Claude (adb) | M16: 46299 | N16: 1.0.0+1 debug | O16: emulator-5554 / Android 14 | Q16: Registered number: 'This mobile number is already registered. Log in instead.' under the mobile field. Server password refusal appears under the password field. (Email/address server errors not triggered.)
A17: BL-AUTH-016 | B17: Authentication & session | C17: Sign-up | D17: Successful sign-up signs the user in | E17: Enter the correct code | F17: 'Welcome to Medibook, <first name>!' and Home; booking 'for myself' works immediately. | G17: P0 | H17: State | I17: lib/features/auth/presentation/screen/verify_code_screen.dart:125 | J17: KB-05 | K17: Blocked | L17: Claude (adb) | M17: 46299 | N17: 1.0.0+1 debug | O17: emulator-5554 / Android 14 | Q17: KB-05: the server sends no SMS, so a correct sign-up code cannot be entered.
A18: BL-AUTH-017 | B18: Authentication & session | C18: OTP verification | D18: Local checks before any request | E18: Tap Verify with nothing entered and with fewer digits | F18: 'Enter the code' / 'Enter all N digits'; no request is sent. The number of boxes equals the server's code length. | G18: P1 | H18: Boundary | I18: lib/features/auth/presentation/controllers/verify_controller.dart:64 | K18: Pass | L18: Claude (adb) | M18: 46299 | N18: 1.0.0+1 debug | O18: emulator-5554 / Android 14 | Q18: Verify with nothing entered: 'Enter the code'; with 2 digits: 'Enter all 4 digits'. 4 boxes match the server's otp_length (4).
A19: BL-AUTH-018 | B19: Authentication & session | C19: OTP verification | D19: Wrong, expired and exhausted codes | E19: 1. Enter a wrong code 2. Wait over 180 s and enter the code 3. Enter 3 wrong codes | F19: 'That code is not right. Check it and try again. 2 attempts left.' / 'That code has expired. Request a new one.' / 'Too many wrong codes. Request a new code to continue.' | G19: P0 | H19: Error handling | I19: lib/core/network/network_exceptions.dart:478 | J19: KB-05 | K19: Pass | L19: Claude (adb) | M19: 46299 | N19: 1.0.0+1 debug | O19: emulator-5554 / Android 14 | Q19: Wrong codes: 'That code is not right. Check it and try again. 2 attempts left.' -> '1 attempt left.' -> 'Too many wrong codes. Request a new code to continue.' After 186 s: 'The code has expired.' (Minor: after 'Resend code' the old 'Too many wrong codes' error stays on screen.)
A20: BL-AUTH-019 | B20: Authentication & session | C20: OTP verification | D20: Resend replaces the challenge | E20: 1. Tap 'Resend Code' 2. Enter the old code, then the new one | F20: 'Code re-sent to your mobile number'; the old code fails, the new one works. | G20: P1 | H20: State | I20: lib/features/auth/presentation/controllers/verify_controller.dart:92 | J20: KB-05 | K20: Blocked | L20: Claude (adb) | M20: 46299 | N20: 1.0.0+1 debug | O20: emulator-5554 / Android 14 | Q20: KB-05: no SMS on this server, so old-vs-new code cannot be compared. Verified only that 'Resend code' shows the toast 'Code re-sent to your mobile number'.
A21: BL-AUTH-020 | B21: Authentication & session | C21: OTP verification | D21: Resend cooldown and code-expiry countdown | E21: Arrive on the verify screen and tap 'Resend Code' immediately, several times | F21: A 30 s cooldown / countdown is expected. The code leaves the button always tappable and relies on the server's 'too many attempts' answer. | G21: P1 | H21: Verify gap | I21: lib/features/auth/presentation/screen/verify_code_screen.dart:283 | J21: KB-05 | K21: Pass | L21: Claude (adb) | M21: 46300 | N21: 1.0.0+1 debug | O21: emulator-5554 / Android 14 | P21: DEF-002 | Q21: FIXED AND RETESTED (5 Oct 2026, rebuilt debug build; DEF-002). The code screen now counts down to the challenge's resend_after_seconds before Resend is offered ('Resend in 00:15', not tappable), and shows the code's own life from expires_at ('Code expires in 02:46'; after expiry 'This code has expired. Tap Resend Code for a new one.'). A resend restarts both. Emulator: mobile sign-in for Sanjay -> 'Code expires in 02:46' and 'Didn't get the code? Resend in 00:15'. Test added (sign_in_routing_test.dart). First observed: No resend cooldown or countdown on the verify screen: 'Resend code' is tappable immediately on arrival; tapping it at once gave the server banner 'Too many attempts. Please wait a moment and try again.' No expiry countdown for the 180 s code either.
A22: BL-AUTH-021 | B22: Authentication & session | C22: OTP verification | D22: Verify screen opened without a code request | E22: 1. Open the verify deep link with no parameters 2. Enter a code | F22: 'This code request has expired. Go back and ask for a new code.' | G22: P2 | H22: Error handling | I22: lib/features/auth/presentation/controllers/verify_controller.dart:53 | K22: Pass | L22: Claude (adb) | M22: 46300 | N22: 1.0.0+1 debug | O22: emulator-5554 / Android 14 | Q22: PASS (5 Oct 2026, debug build). Still not reachable from outside the app, which is intended: medibook://verify opens 'Page not found' and every in-app path passes a code request. The guard itself is covered by test/features/auth/verify_purpose_test.dart: opened with no code request, entering 1234 shows 'This code request has expired. Go back and ask for a new code.' and nothing is sent to the server. Earlier note: Not reachable by a user: medibook://verify (no parameters) opens 'Page not found', so the orphan verify screen cannot be opened from outside the app.
A23: BL-AUTH-022 | B23: Authentication & session | C23: OTP verification | D23: Phone-change purpose on the generic verify screen | E23: 1. While signed in open /verify?purpose=phone-change&ch=x&len=4 2. Enter any 4 digits | F23: Nothing should be 'verified'. The code accepts any well-formed code with no server call and opens Edit Profile (no number actually changes). | G23: P2 | H23: Verify gap | I23: lib/features/auth/presentation/controllers/verify_controller.dart:149 | K23: Pass | L23: Claude (adb) | M23: 46300 | N23: 1.0.0+1 debug | O23: emulator-5554 / Android 14 | P23: DEF-072 | Q23: PASS (5 Oct 2026, debug build). FIXED (DEF-072): the generic verify screen no longer has a phone-change purpose (the number change confirms both codes on its own /profile/phone screen, which nothing else used). A /verify?purpose=phone-change&ch=x&len=4 link is now checked by the server like any other code, so a made-up code is refused and nothing is 'verified'. Covered by test/features/auth/verify_purpose_test.dart; the route is still not open to external links. Earlier note: Not reachable by a user: the verify route is not exposed to external links (medibook://verify -> 'Page not found'); no in-app path opens /verify with purpose=phone-change.
A24: BL-AUTH-023 | B24: Authentication & session | C24: OTP verification | D24: What a correct code does depends on the flow | E24: Complete sign-up, mobile sign-in and password reset | F24: Buttons read 'Verify & Create Account' / 'Verify & Log In' / 'Verify'; destinations are Home, Home and the new-password screen. | G24: P1 | H24: Rule | I24: lib/features/auth/presentation/screen/verify_code_screen.dart:124 | J24: KB-05 | K24: Blocked | L24: Claude (adb) | M24: 46299 | N24: 1.0.0+1 debug | O24: emulator-5554 / Android 14 | Q24: KB-05: correct codes are not obtainable. Observed only the mobile sign-in label 'Verify & Log In' and title 'Verify Mobile'.
A25: BL-AUTH-024 | B25: Authentication & session | C25: Password sign-in | D25: Identifier must be an email or a full +91 number | E25: 1. Submit empty 2. Submit '9845658525' on the email/mobile field 3. Submit with an empty password | F25: 'Enter your email or mobile number' / 'Enter a valid email address or mobile number' / 'Enter your password'. Confirm a bare 10-digit number should be rejected here. | G25: P1 | H25: Boundary | I25: lib/features/auth/presentation/controllers/login_form_controller.dart:49 | K25: Pass | L25: Claude (adb) | M25: 46299 | N25: 1.0.0+1 debug | O25: emulator-5554 / Android 14 | Q25: Empty: 'Enter your email or mobile number' + 'Enter your password'. Bare 10-digit number: 'Enter a valid email address or mobile number' (a +91 prefix is required on this tab — confirm intended).
A26: BL-AUTH-025 | B26: Authentication & session | C26: Password sign-in | D26: Malformed input never spends a server attempt | E26: Submit a malformed identifier with a proxy attached | F26: No sign-in request is sent; attempts remaining is unchanged. | G26: P1 | H26: Rule | I26: lib/features/auth/application/usecases/login.dart:116 | K26: Pass | L26: Claude (adb) | M26: 46299 | N26: 1.0.0+1 debug | O26: emulator-5554 / Android 14 | Q26: No proxy available; verified indirectly: after two malformed submissions the first real wrong password still reported '4 attempts left', so no server attempt was spent.
A27: BL-AUTH-026 | B27: Authentication & session | C27: Password sign-in | D27: Wrong password shows attempts left | E27: Enter wrong passwords one at a time | F27: 'That email or number and password do not match an account. 4 attempts left.' counting down to '1 attempt left.' | G27: P0 | H27: Error handling | I27: lib/core/network/network_exceptions.dart:330 | K27: Pass | L27: Claude (adb) | M27: 46299 | N27: 1.0.0+1 debug | O27: emulator-5554 / Android 14 | Q27: Wrong passwords on a spare account: 'That email or number and password do not match an account. 3 attempts left.' -> '2 attempts left.' -> '1 attempt left.' (the count started at 4 on the first attempt earlier in the run).
A28: BL-AUTH-027 | B28: Authentication & session | C28: Password sign-in | D28: Blocked account | E28: Sign in to a blocked account | F28: 'This account has been blocked. Contact Medibook support.'; attempts counter unchanged. | G28: P1 | H28: Error handling | I28: lib/core/network/network_exceptions.dart:330 | K28: Blocked | L28: Claude (adb) | M28: 46299 | N28: 1.0.0+1 debug | O28: emulator-5554 / Android 14 | Q28: Seed data: every seeded patient account is active; no blocked account to sign in to.
A29: BL-AUTH-028 | B29: Authentication & session | C29: Password sign-in | D29: What is stored after sign-in | E29: 1. Sign in 2. Inspect secure storage and the Hive auth box on a debug build | F29: Tokens and session id only in secure storage; the Hive box holds id, name, phone and flags — no tokens. | G29: P0 | H29: Rule | I29: lib/features/auth/infrastructure/repositories/auth_repository_impl.dart:246 | K29: Pass | L29: Claude (adb) | M29: 46299 | N29: 1.0.0+1 debug | O29: emulator-5554 / Android 14 | Q29: On-device inspection (run-as): no JWT in any Hive file or plain prefs; tokens live only in FlutterSecureStorage (encrypted values). Hive auth box holds user id, first/last name, phone, has_password, version, last_login_at.
A30: BL-AUTH-029 | B30: Authentication & session | C30: OTP sign-in | D30: Unregistered number is indistinguishable at 'Send Code' | E30: 1. Request a code for a number with no account 2. Enter any code | F30: Verify screen opens normally; 'That code is not right. Check it and try again.' | G30: P1 | H30: Rule | I30: lib/features/auth/infrastructure/repositories/auth_repository_impl.dart:63 | K30: Pass | L30: Claude (adb) | M30: 46299 | N30: 1.0.0+1 debug | O30: emulator-5554 / Android 14 | Q30: Unregistered number 9123456781: 'Send Code' opens the normal verify screen ('We sent a 4-digit code to +919123456781.'); a code gives 'That code is not right. Check it and try again. 2 attempts left.' — no hint that the number has no account.
A31: BL-AUTH-030 | B31: Authentication & session | C31: OTP sign-in | D31: Switching Email / Mobile tab resets errors | E31: 1. Cause an error on one tab 2. Switch tabs | F31: Errors clear; button reads 'Log In' on Email and 'Send Code' on Mobile. | G31: P3 | H31: State | I31: lib/features/auth/presentation/screen/login_screen.dart:146 | K31: Pass | L31: Claude (adb) | M31: 46299 | N31: 1.0.0+1 debug | O31: emulator-5554 / Android 14 | Q31: Switching Email -> Mobile cleared the offline banner and field errors; button reads 'Log In' on Email and 'Send Code' on Mobile.
A32: BL-AUTH-031 | B32: Authentication & session | C32: Lockout | D32: Attempt warnings escalate | E32: Enter wrong passwords one by one | F32: Amber 'Sign-in attempts — N attempts left…' while more than one remains; red 'One attempt left' at one. | G32: P1 | H32: State | I32: lib/features/auth/presentation/components/lockout_notice.dart:91 | K32: Pass | L32: Claude (adb) | M32: 46299 | N32: 1.0.0+1 debug | O32: emulator-5554 / Android 14 | Q32: Amber 'Sign-in attempts — N attempts left before sign-in is paused for 60 seconds.' while more than one remains; red 'One attempt left — The next wrong password pauses sign-in for 60 seconds. Use "Forgot password?" if you are not sure.' at one.
A33: BL-AUTH-032 | B33: Authentication & session | C33: Lockout | D33: Warning text states the real pause length | E33: 1. Read the warning before lockout 2. Get locked out and read the countdown | F33: They should agree. The warning says 'paused for 60 seconds' while the server locks for about an hour. | G33: P1 | H33: Verify gap | I33: lib/app/config/constants.dart:50 | K33: Pass | L33: Claude (adb) | M33: 46300 | N33: 1.0.0+1 debug | O33: emulator-5554 / Android 14 | P33: DEF-003 | Q33: FIXED (5 Oct 2026; DEF-003); checked by automated test, not on the emulator (five wrong passwords would lock a shared seeded account for an hour). The warnings now name the server's real pause, one hour (API §4, 423 AUTH_LOCKED_OUT): '2 attempts left before sign-in is paused for 1 hour.' and 'The next wrong password pauses sign-in for 1 hour.' (AppConstants.loginLockoutCooldown = 1 hour; lockout_notice.dart words it). The countdown itself still runs to the server's locked_until. Test added (lockout_notice_test.dart). First observed: The warnings say sign-in will be 'paused for 60 seconds', but after the fifth failure the lockout countdown starts at 59:57 — about one hour. The warning understates the pause sixty-fold.
A34: BL-AUTH-033 | B34: Authentication & session | C34: Lockout | D34: Lockout disables sign-in with a live countdown | E34: Fail 5 times | F34: 'Too many failed attempts — Sign-in is paused for your security. Try again in mm:ss.'; fields and button disabled. | G34: P0 | H34: State | I34: lib/features/auth/application/usecases/login.dart:141 | K34: Pass | L34: Claude (adb) | M34: 46299 | N34: 1.0.0+1 debug | O34: emulator-5554 / Android 14 | Q34: After the fifth failure: 'Too many failed attempts — Sign-in is paused for your security. Try again in 59:57.' with a live countdown; the Log In button is disabled ('paused after too many failed attempts').
A35: BL-AUTH-034 | B35: Authentication & session | C35: Lockout | D35: Lockout survives a force-quit and lifts on its own | E35: 1. Get locked out 2. Kill and relaunch 3. Wait for 00:00 | F35: Countdown still showing after relaunch; at zero the form re-enables without restarting. | G35: P0 | H35: State | I35: lib/features/auth/application/providers/auth_provider.dart:292 | K35: Pass | L35: Claude (adb) | M35: 46299 | N35: 1.0.0+1 debug | O35: emulator-5554 / Android 14 | Q35: After force-stop and relaunch the lockout notice is still shown with the countdown continuing ('again in 59:36'). The automatic lift at 00:00 was not waited for (one hour).
A36: BL-AUTH-035 | B36: Authentication & session | C36: Lockout | D36: Lockout scope on a shared device | E36: 1. Lock account A 2. On the same device try to sign in as B, sign up, and use Forgot password | F36: Decide what is correct: the code blocks all of these locally while A's lock runs, although the warning itself suggests using 'Forgot password?'. | G36: P1 | H36: Verify gap | I36: lib/features/auth/application/providers/auth_provider.dart:268 | K36: Pass | L36: Claude (adb) | M36: 46300 | N36: 1.0.0+1 debug | O36: emulator-5554 / Android 14 | P36: DEF-004 | Q36: FIXED (5 Oct 2026; DEF-004); checked by automated test, not on the emulator (it needs a real one-hour lockout of a shared account). The lockout is now remembered with the account it belongs to (locked_identifier next to locked_until) and applies only to that account: another account on the same phone can sign in, ask for a code or reset a password; the locked account is still refused without a request. On the sign-in screen the warning and the disabled Log In follow the account typed, and the account field stays editable. A lockout remembered before this change (no account) still applies to all. Tests added (lockout_scope_test.dart). First observed: With the device locked out by one account's failed attempts, 'Forgot password?' for a DIFFERENT account's number is refused locally: 'Too many failed attempts. Try again in 60 minutes.' The lock is device-wide — nobody else can sign in, sign up or reset a password on this device for an hour, and it blocks the very 'Forgot password?' route the last-attempt warning recommends.
A37: BL-AUTH-036 | B37: Authentication & session | C37: Lockout | D37: Wrong OTP must not show a password-attempt warning | E37: 1. On mobile sign-in enter one wrong code 2. Go back to the sign-in screen | F37: No password warning. The code shows '2 attempts left before sign-in is paused…' although no password was tried. | G37: P2 | H37: Verify gap | I37: lib/features/auth/application/usecases/login.dart:144 | K37: Pass | L37: Claude (adb) | M37: 46300 | N37: 1.0.0+1 debug | O37: emulator-5554 / Android 14 | P37: DEF-005 | Q37: FIXED AND RETESTED (5 Oct 2026, rebuilt debug build; DEF-005). A wrong sign-in code no longer sets the password-attempt count: its attempts stay on the code screen. Emulator: mobile sign-in for Sanjay, code 0000 -> 'That code is not right. Check it and try again. 2 attempts left.'; Back -> the sign-in screen (Mobile and Email tabs) shows no 'Sign-in attempts' warning. Then signed in again by email. Test added (lockout_scope_test.dart). First observed: After one wrong OTP on mobile sign-in, going back to the sign-in screen shows the password warning 'Sign-in attempts — 2 attempts left before sign-in is paused for 60 seconds.' although no password was tried (OTP attempts are written into the password-attempt counter).
A38: BL-AUTH-037 | B38: Authentication & session | C38: Lockout | D38: A network failure clears the attempts notice | E38: 1. Enter a wrong password 2. Submit again in airplane mode | F38: Offline message; the attempts notice is gone (count unknown). | G38: P3 | H38: State | I38: lib/features/auth/application/providers/auth_provider.dart:250 | K38: Pass | L38: Claude (adb) | M38: 46299 | N38: 1.0.0+1 debug | O38: emulator-5554 / Android 14 | Q38: After a wrong password (attempts notice visible), submitting in airplane mode shows 'You appear to be offline. Check your connection and try again.' and the attempts notice is gone.
A39: BL-AUTH-038 | B39: Authentication & session | C39: Forgot / reset password | D39: Email identifier does not reveal the phone number | E39: Start a reset with a registered email | F39: 'We sent a 4-digit code to your mobile number.' — no digits shown. | G39: P1 | H39: Rule | I39: lib/features/auth/presentation/screen/forgot_password_screen.dart:81 | K39: Pass | L39: Claude (adb) | M39: 46299 | N39: 1.0.0+1 debug | O39: emulator-5554 / Android 14 | Q39: Bad email: 'Enter a valid email address'. Registered email: verify screen says 'We sent a 4-digit code to your mobile number.' — no digits revealed.
A40: BL-AUTH-039 | B40: Authentication & session | C40: Forgot / reset password | D40: Reset permission lives only in memory | E40: 1. Verify the reset code 2. Kill the app on the new-password screen 3. Reopen it and submit | F40: 'That reset link has expired. Request a new code to continue.'; no request is sent. | G40: P2 | H40: State | I40: lib/features/auth/presentation/controllers/reset_form_controller.dart:65 | J40: KB-05 | K40: Blocked | L40: Claude (adb) | M40: 46299 | N40: 1.0.0+1 debug | O40: emulator-5554 / Android 14 | Q40: KB-05: the reset code is never delivered on this server, so the flow cannot pass the verify step.
...

Sheet Checklist
A1: ID | B1: Module | C1: Screen / Area | D1: Test case | E1: Steps | F1: Expected result | G1: Priority | H1: Type | I1: Platform | J1: Needs / Blocker | K1: Status | L1: Tester | M1: Date tested | N1: Build | O1: Device / OS | P1: Defect ID | Q1: Notes / Actual result
A2: ENV-001 | B2: 00 Test environment & prerequisites | C2: Backend | D2: API reachable over HTTPS with a CA-signed certificate | E2: 1. Run curl against <host>/api/v1/shared/health without -k 2. Open the same URL in a device browser | F2: 200 response, no certificate warning. A self-signed certificate is not acceptable for a production run. | G2: P0 | H2: Release | I2: Both | J2: KB-03 | K2: Blocked | L2: Claude (adb) | M2: 46300 | N2: 1.0.0+1 debug | O2: emulator-5554 / Android 14 | Q2: 5 Oct 2026: curl without -k to https://62.171.151.149:8443/api/v1/shared/health fails (HTTP 000): the certificate is self-signed (subject and issuer 'CN=localhost', valid to 1 Jan 2029). Backend blocker BB-23 (KB-03): a CA-signed certificate on a real host name.
A3: ENV-002 | B3: 00 Test environment & prerequisites | C3: Build | D3: Build under test is a release build with production defines | E3: 1. Build with --release and MEDIBOOK_ENV=prod, MEDIBOOK_API_BASE_URL=<prod host>, MEDIBOOK_DEMO=false, MEDIBOOK_ALLOW_BAD_CERT=false 2. Install on a device 3. Record the build number in the Read Me sheet | F3: App starts and talks to the production/pre-prod host. No debug banner. The integration-server IP is not used. | G3: P0 | H3: Release | I3: Both | J3: KB-07 | K3: Blocked | L3: Claude (adb) | M3: 46300 | N3: 1.0.0+1 debug | O3: emulator-5554 / Android 14 | Q3: 5 Oct 2026: No production or pre-production host has been provided, so a --release build with MEDIBOOK_ENV=prod and MEDIBOOK_API_BASE_URL=<prod host> cannot be pointed anywhere. App side is ready: in a prod build the config check refuses demo mode and certificate bypass (see INS-007). Backend blocker BB-24 (KB-07).
A4: ENV-003 | B4: 00 Test environment & prerequisites | C4: Payments | D4: Razorpay keys are configured on the backend | E4: 1. Create a booking 2. Inspect the payment_order in the response (proxy) | F4: payment_order.key_id is a real rzp_test_/rzp_live_ key and gateway_order_id is a real Razorpay order (not order_fake...). | G4: P0 | H4: Release | I4: Both | J4: KB-02 | K4: Blocked | L4: Claude (adb) | M4: 46300 | N4: 1.0.0+1 debug | O4: emulator-5554 / Android 14 | Q4: 5 Oct 2026: A booking's payment_order has key_id '' and gateway_order_id 'order_fake9b2dc0c9fa7447'. Razorpay is still the in-process fake. Backend blocker BB-16 (KB-02).
A5: ENV-004 | B5: 00 Test environment & prerequisites | C5: Storage | D5: File storage host resolves and accepts uploads | E5: 1. POST /shared/files/uploads 2. PUT a file to the returned upload_url | F5: upload_url points at a resolvable host; PUT returns 2xx; the file reaches status 'clean'. | G5: P0 | H5: Release | I5: Both | J5: KB-01 | K5: Blocked | L5: Claude (adb) | M5: 46300 | N5: 1.0.0+1 debug | O5: emulator-5554 / Android 14 | Q5: 5 Oct 2026: POST /shared/files/uploads returns 201, but upload_url points at storage.fake.local, which does not resolve (PUT fails: 'nodename nor servname provided'). Backend blocker BB-17 (KB-01).
A6: ENV-005 | B6: 00 Test environment & prerequisites | C6: SMS | D6: OTP SMS is delivered to real test numbers | E6: 1. Start an OTP login for a test number 2. Wait for the SMS | F6: SMS arrives within 30 s with a 4-digit code. (India: DLT sender ID and template are registered.) | G6: P0 | H6: Release | I6: Both | J6: KB-05 | K6: Blocked | L6: Claude (adb) | M6: 46300 | N6: 1.0.0+1 debug | O6: emulator-5554 / Android 14 | Q6: 5 Oct 2026: No SMS is sent on the integration server and the code is not exposed. Backend blocker BB-01 (KB-05).
A7: ENV-006 | B7: 00 Test environment & prerequisites | C7: Push | D7: Push provider configured for Android and iOS | E7: Confirm FCM project, APNs key and app registration exist for the release bundle IDs | F7: A test push sent from the console reaches both platforms. | G7: P0 | H7: Release | I7: Both | J7: KB-04 | K7: Blocked | L7: Claude (adb) | M7: 46300 | N7: 1.0.0+1 debug | O7: emulator-5554 / Android 14 | Q7: 5 Oct 2026: The app has no push SDK (no Firebase/FCM in pubspec.yaml; KB-04), and there is no FCM project or APNs key for the release bundle ids. Needs the owner's decision to add Firebase Messaging plus the project's config files (same as BL-NOTIF-017).
A8: ENV-007 | B8: 00 Test environment & prerequisites | C8: Test data | D8: Test accounts are prepared | E8: Prepare: (a) unregistered mobile number, (b) account with password, (c) OTP-only account, (d) account with 2+ family members, (e) blocked account, (f) account with a completed paid visit, (g) account with a pending deletion request | F8: All seven accounts exist and their credentials are recorded outside this workbook. | G8: P0 | H8: Release | I8: Both | K8: Blocked | L8: Claude (adb) | M8: 46300 | N8: 1.0.0+1 debug | O8: emulator-5554 / Android 14 | Q8: 5 Oct 2026: Available: (b) password account (Sanjay Varma), (d) 2+ family members (Sanjay: Tara, Ishaan), (f) completed visits (Sanjay: 5 completed). Missing: (a) a usable unregistered number (sign-up needs an OTP, BB-01), (c) OTP-only account (BB-01), (e) blocked account (BB-02), (g) account with a pending deletion request (BB-03, a throwaway account is needed).
